function funcionarOuNao(valor, chanceErro) {
    return new Promise((resolve, reject) => {
        try {
            con.log()
            if(Math.random() < chanceErro) {
                reject('Ocorreu um erro!')
            } else {
                resolve(valor)
            }            
        } catch (e) {
            reject(e)
        }
    })
}

funcionarOuNao('Testando', 0.9)
    .then(v => console.log(`Valor: ${v}`))
    .then(
        v => consol.log(v),
        err => console.log(`Erro especÃ­fico: ${err}`)
    )
    .then(() => console.log('Quase Fim'))
    .catch(err => console.log(`Erro Geral: ${err}`))
    .then(() => console.log('Fim!'))